<?xml version="1.0"?>
<robot name="omni_bot">

  <!-- Material Definitions -->
  <material name="gray">
    <color rgba="0.5 0.5 0.5 1"/>
  </material>
  <material name="black">
    <color rgba="0.1 0.1 0.1 1"/>
  </material>

  <!-- Base Link -->
  <link name="base_footprint">
    <inertial>
      <origin xyz="0 0 0" rpy="0 0 0"/>
      <mass value="2.0"/>
      <inertia ixx="0.052" ixy="0.0" ixz="0.0" iyy="0.052" iyz="0.0" izz="0.01"/>
    </inertial>
    <visual>
      <origin xyz="0 0 0.05" rpy="0 0 0"/>
      <geometry>
        <box size="0.5 0.5 0.1"/>
      </geometry>
      <material name="gray"/>
    </visual>
    <collision>
      <origin xyz="0 0 0.05" rpy="0 0 0"/>
      <geometry>
        <box size="0.5 0.5 0.1"/>
      </geometry>
    </collision>
  </link>

  <!-- Wheel Links (with correct orientation) -->
  <link name="wheel_front_left">
    <inertial>
      <origin xyz="0 0 0" rpy="1.5708 0 0"/>
      <mass value="0.1"/>
      <inertia ixx="0.0001" ixy="0.0" ixz="0.0" iyy="0.0001" iyz="0.0" izz="0.0005"/>
    </inertial>
    <visual>
      <origin xyz="0 0 0" rpy="1.5708 0 0"/>
      <geometry>
        <cylinder length="0.05" radius="0.075"/>
      </geometry>
      <material name="black"/>
    </visual>
    <collision>
      <origin xyz="0 0 0" rpy="1.5708 0 0"/>
      <geometry>
        <cylinder length="0.05" radius="0.075"/>
      </geometry>
      <surface>
  <friction>
    <ode>
      <mu>3.0</mu>         <!-- friction in primary direction -->
      <mu2>3.0</mu2>       <!-- friction in orthogonal direction -->
    </ode>
  </friction>
</surface>
    </collision>
  </link>

  <link name="wheel_front_right">
    <inertial>
      <origin xyz="0 0 0" rpy="1.5708 0 0"/>
      <mass value="0.1"/>
      <inertia ixx="0.0001" ixy="0.0" ixz="0.0" iyy="0.0001" iyz="0.0" izz="0.0005"/>
    </inertial>
    <visual>
      <origin xyz="0 0 0" rpy="1.5708 0 0"/>
      <geometry>
        <cylinder length="0.05" radius="0.075"/>
      </geometry>
      <material name="black"/>
    </visual>
    <collision>
      <origin xyz="0 0 0" rpy="1.5708 0 0"/>
      <geometry>
        <cylinder length="0.05" radius="0.075"/>
      </geometry>
      <surface>
  <friction>
    <ode>
      <mu>3.0</mu>         <!-- friction in primary direction -->
      <mu2>3.0</mu2>       <!-- friction in orthogonal direction -->
    </ode>
  </friction>
</surface>

    </collision>
  </link>

  <link name="wheel_back_left">
    <inertial>
      <origin xyz="0 0 0" rpy="1.5708 0 0"/>
      <mass value="0.1"/>
      <inertia ixx="0.0001" ixy="0.0" ixz="0.0" iyy="0.0001" iyz="0.0" izz="0.0005"/>
    </inertial>
    <visual>
      <origin xyz="0 0 0" rpy="1.5708 0 0"/>
      <geometry>
        <cylinder length="0.05" radius="0.075"/>
      </geometry>
      <material name="black"/>
    </visual>
    <collision>
      <origin xyz="0 0 0" rpy="1.5708 0 0"/>
      <geometry>
        <cylinder length="0.05" radius="0.075"/>
      </geometry>
      <surface>
  <friction>
    <ode>
      <mu>3.0</mu>         <!-- friction in primary direction -->
      <mu2>3.0</mu2>       <!-- friction in orthogonal direction -->
    </ode>
  </friction>
</surface>
    </collision>
  </link>

  <link name="wheel_back_right">
    <inertial>
      <origin xyz="0 0 0" rpy="1.5708 0 0"/>
      <mass value="0.1"/>
      <inertia ixx="0.0001" ixy="0.0" ixz="0.0" iyy="0.0001" iyz="0.0" izz="0.0005"/>
    </inertial>
    <visual>
      <origin xyz="0 0 0" rpy="1.5708 0 0"/>
      <geometry>
        <cylinder length="0.05" radius="0.075"/>	
      </geometry>
      <material name="black"/>
    </visual>
    <collision>
      <origin xyz="0 0 0" rpy="1.5708 0 0"/>
      <geometry>
        <cylinder length="0.05" radius="0.075"/>
      </geometry>
            <surface>
  <friction>
    <ode>
      <mu>3.0</mu>         <!-- friction in primary direction -->
      <mu2>3.0</mu2>       <!-- friction in orthogonal direction -->
    </ode>
  </friction>
</surface>
    </collision>
  </link>

  <!-- Joints -->
  <joint name="wheel_front_left_joint" type="continuous">
    <parent link="base_footprint"/>
    <child link="wheel_front_left"/>
    <origin xyz="0.25 0.25 0.025" rpy="0 0 0"/>
    <axis xyz="0 1 0"/>
  </joint>
  <joint name="wheel_front_right_joint" type="continuous">
    <parent link="base_footprint"/>
    <child link="wheel_front_right"/>	
    <origin xyz="0.25 -0.25 0.025" rpy="0 0 0"/>
    <axis xyz="0 1 0"/>
  </joint>
  <joint name="wheel_back_left_joint" type="continuous">
    <parent link="base_footprint"/>
    <child link="wheel_back_left"/>
    <origin xyz="-0.25 0.25 0.025" rpy="0 0 0"/>
    <axis xyz="0 1 0"/>
  </joint>
  <joint name="wheel_back_right_joint" type="continuous">
    <parent link="base_footprint"/>
    <child link="wheel_back_right"/>
    <origin xyz="-0.25 -0.25 0.025" rpy="0 0 0"/>
    <axis xyz="0 1 0"/>
  </joint>

  <!-- Gazebo Plugin for Omnidirectional Drive -->
  <gazebo>
    <plugin name="rosa_controller" filename="libgazebo_ros_omni_drive.so">
      <ros>
        <namespace>/omni_bot</namespace>
        <remapping>cmd_vel:=/omni_bot/cmd_vel</remapping>
        <remapping>odom:=/omni_bot/odom</remapping>
      </ros>
      <commandTopic>/omni_bot/cmd_vel</commandTopic>
      <odometryTopic>/omni_bot/odom</odometryTopic>
      <odometryFrame>odom</odometryFrame>
      <odometryRate>20.0</odometryRate>
      <robotBaseFrame>base_footprint</robotBaseFrame>
      <wheel_radius>0.075</wheel_radius>
      <base_length>0.5</base_length>
      <base_width>0.5</base_width>
      <front_left_joint>wheel_front_left_joint</front_left_joint>
      <front_right_joint>wheel_front_right_joint</front_right_joint>
      <rear_left_joint>wheel_back_left_joint</rear_left_joint>
      <rear_right_joint>wheel_back_right_joint</rear_right_joint>
      <wheel_max_speed>20.0</wheel_max_speed>
      <wheel_acceleration>10.0</wheel_acceleration>
      <joint_config>1 1 1 1</joint_config>
    </plugin>
  </gazebo>


  <!-- CAMERA JOINT -->
  <joint name="camera_joint" type="fixed">
    <parent link="base_footprint"/>
    <child link="camera_link"/>
    <origin xyz="0 0 0.3" rpy="0 0 0"/>
  </joint>

  <!-- CAMERA LINK -->
  <link name="camera_link">
    <visual>
      <geometry>
        <box size="0.03 0.03 0.03"/>
      </geometry>
      <material name="black"/>
    </visual>
    <inertial>
      <mass value="0.1"/>
      <inertia ixx="0.0001" ixy="0.0" ixz="0.0" iyy="0.0001" iyz="0.0" izz="0.0001"/>
      <origin xyz="0 0 0" rpy="0 0 0"/>
    </inertial>
  </link>

  <!-- CAMERA OPTICAL LINK -->
  <joint name="camera_optical_joint" type="fixed">
    <parent link="camera_link"/>
    <child link="camera_link_optical"/>
    <origin xyz="0 0 0" rpy="-1.5708 0 -1.5708"/>

  </joint>

  <link name="camera_link_optical"></link>

  <!-- GAZEBO CAMERA PLUGIN -->
  <gazebo reference="camera_link">
    <material>Gazebo/Black</material>
    <sensor name="camera" type="camera">
      <pose>0 0 0 0 0 0</pose>
      <visualize>true</visualize>
      <update_rate>15.0</update_rate>
      <camera>
        <horizontal_fov>1.047</horizontal_fov>
        <image>
          <width>640</width>
          <height>480</height>
          <format>R8G8B8</format>
        </image>
        <clip>
          <near>0.05</near>
          <far>10.0</far>
        </clip>
      </camera>
      <plugin name="camera_controller" filename="libgazebo_ros_camera.so">
        <frame_name>camera_link_optical</frame_name>
      </plugin>
    </sensor>
  </gazebo>
  
<gazebo>
  <plugin name="joint_state_publisher" filename="libgazebo_ros_joint_state_publisher.so">
    <update_rate>50.0</update_rate>
  </plugin>
</gazebo>

</robot>

