<?xml version="1.0"?>
<robot name="omni_bot">

  <!-- Material Definitions -->
  <material name="gray">
    <color rgba="0.5 0.5 0.5 1"/>
  </material>
  <material name="black">
    <color rgba="0.1 0.1 0.1 1"/>
  </material>

  <!-- Base Link -->
  <link name="base_footprint">
    <inertial>
      <origin xyz="0 0 0" rpy="0 0 0"/>
      <mass value="5.0"/>
      <inertia ixx="0.052" ixy="0.0" ixz="0.0" iyy="0.052" iyz="0.0" izz="0.01"/>
    </inertial>
    <visual>
      <origin xyz="0 0 0.05" rpy="0 0 0"/>
      <geometry>
        <box size="0.5 0.5 0.1"/>
      </geometry>
      <material name="gray"/>
    </visual>
    <collision>
      <origin xyz="0 0 0.05" rpy="0 0 0"/>
      <geometry>
        <box size="0.5 0.5 0.1"/>
      </geometry>
    </collision>
  </link>

  <!-- Wheel Links (with correct orientation) -->
  <link name="wheel_front_left">
    <inertial>
      <origin xyz="0 0 0" rpy="1.5708 0 0"/>
      <mass value="0.3"/>
      <inertia ixx="0.0002" ixy="0.0" ixz="0.0" iyy="0.0002" iyz="0.0" izz="0.0001"/>
    </inertial>
    <visual>
      <origin xyz="0 0 0" rpy="1.5708 0 0"/>
      <geometry>
        <cylinder length="0.05" radius="0.075"/>
      </geometry>
      <material name="black"/>
    </visual>
    <collision>
      <origin xyz="0 0 0" rpy="1.5708 0 0"/>
      <geometry>
        <cylinder length="0.05" radius="0.075"/>
      </geometry>
    </collision>
  </link>

  <link name="wheel_front_right">
    <inertial>
      <origin xyz="0 0 0" rpy="1.5708 0 0"/>
      <mass value="0.3"/>
      <inertia ixx="0.0002" ixy="0.0" ixz="0.0" iyy="0.0002" iyz="0.0" izz="0.0001"/>
    </inertial>
    <visual>
      <origin xyz="0 0 0" rpy="1.5708 0 0"/>
      <geometry>
        <cylinder length="0.05" radius="0.075"/>
      </geometry>
      <material name="black"/>
    </visual>
    <collision>
      <origin xyz="0 0 0" rpy="1.5708 0 0"/>
      <geometry>
        <cylinder length="0.05" radius="0.075"/>
      </geometry>
    </collision>
  </link>

  <link name="wheel_back_left">
    <inertial>
      <origin xyz="0 0 0" rpy="1.5708 0 0"/>
      <mass value="0.3"/>
      <inertia ixx="0.0002" ixy="0.0" ixz="0.0" iyy="0.0002" iyz="0.0" izz="0.0001"/>
    </inertial>
    <visual>
      <origin xyz="0 0 0" rpy="1.5708 0 0"/>
      <geometry>
        <cylinder length="0.05" radius="0.075"/>
      </geometry>
      <material name="black"/>
    </visual>
    <collision>
      <origin xyz="0 0 0" rpy="1.5708 0 0"/>
      <geometry>
        <cylinder length="0.05" radius="0.075"/>
      </geometry>
    </collision>
  </link>

  <link name="wheel_back_right">
    <inertial>
      <origin xyz="0 0 0" rpy="1.5708 0 0"/>
      <mass value="0.3"/>
      <inertia ixx="0.0002" ixy="0.0" ixz="0.0" iyy="0.0002" iyz="0.0" izz="0.0001"/>
    </inertial>
    <visual>
      <origin xyz="0 0 0" rpy="1.5708 0 0"/>
      <geometry>
        <cylinder length="0.05" radius="0.075"/>
      </geometry>
      <material name="black"/>
    </visual>
    <collision>
      <origin xyz="0 0 0" rpy="1.5708 0 0"/>
      <geometry>
        <cylinder length="0.05" radius="0.075"/>
      </geometry>
    </collision>
  </link>

  <!-- Joints -->
  <joint name="wheel_front_left_joint" type="continuous">
    <parent link="base_footprint"/>
    <child link="wheel_front_left"/>
    <origin xyz="0.25 0.25 0.025" rpy="0 0 0"/>
    <axis xyz="0 1 0"/>
  </joint>
  <joint name="wheel_front_right_joint" type="continuous">
    <parent link="base_footprint"/>
    <child link="wheel_front_right"/>
    <origin xyz="0.25 -0.25 0.025" rpy="0 0 0"/>
    <axis xyz="0 1 0"/>
  </joint>
  <joint name="wheel_back_left_joint" type="continuous">
    <parent link="base_footprint"/>
    <child link="wheel_back_left"/>
    <origin xyz="-0.25 0.25 0.025" rpy="0 0 0"/>
    <axis xyz="0 1 0"/>
  </joint>
  <joint name="wheel_back_right_joint" type="continuous">
    <parent link="base_footprint"/>
    <child link="wheel_back_right"/>
    <origin xyz="-0.25 -0.25 0.025" rpy="0 0 0"/>
    <axis xyz="0 1 0"/>
  </joint>

  <!-- Gazebo Plugin for Omnidirectional Drive -->
  <gazebo>
    <plugin name="rosa_controller" filename="libgazebo_ros_omni_drive.so">
      <ros>
        <namespace>/omni_bot</namespace>
        <remapping>cmd_vel:=/omni_bot/cmd_vel</remapping>
        <remapping>odom:=/omni_bot/odom</remapping>
      </ros>
      <commandTopic>/omni_bot/cmd_vel</commandTopic>
      <odometryTopic>/omni_bot/odom</odometryTopic>
      <odometryFrame>odom</odometryFrame>
      <odometryRate>20.0</odometryRate>
      <robotBaseFrame>base_footprint</robotBaseFrame>
      <wheel_radius>0.075</wheel_radius>
      <base_length>0.5</base_length>
      <base_width>0.5</base_width>
      <front_left_joint>wheel_front_left_joint</front_left_joint>
      <front_right_joint>wheel_front_right_joint</front_right_joint>
      <rear_left_joint>wheel_back_left_joint</rear_left_joint>
      <rear_right_joint>wheel_back_right_joint</rear_right_joint>
      <wheel_max_speed>20.0</wheel_max_speed>
      <wheel_acceleration>10.0</wheel_acceleration>
      <joint_config>1 1 -1 -1</joint_config>
    </plugin>
  </gazebo>

</robot>

